<?xml version='1.0' encoding='UTF-8'?>
<sdf version="1.6">
  <model name="mud">
    <pose>0 0 0 0 0 0</pose>
    <link name="base_link">
      <inertial>
        <pose>0 0 0 0 0 0</pose>
        <mass>21.4</mass>
        <inertia>
          <ixx>0.18</ixx>
          <ixy>0</ixy>
          <ixz>0</ixz>
          <iyy>0.35</iyy>
          <iyz>0</iyz>
          <izz>0.40</izz>
        </inertia>
      </inertial>
      <velocity_decay>
        <linear>0.2</linear>
        <angular>0.6</angular>
      </velocity_decay>
      <visual name="mud_visual">
        <geometry>
          <mesh>
            <uri>model://mud/meshes/MUD.stl</uri>
            <scale>0.001 0.001 0.001</scale>
          </mesh>
        </geometry>
        <material>
          <ambient>0.15 0.15 0.15 1</ambient>
          <diffuse>0.25 0.25 0.25 1</diffuse>
          <specular>0.1 0.1 0.1 1</specular>
        </material>
      </visual>
      <collision name="mud_collision">
        <pose>0 0 0 0 0 0</pose>
        <geometry><box><size>0.65 0.272 0.118</size></box></geometry>
        <surface>
          <friction>
            <ode>
              <mu>0.4</mu>
              <mu2>0.4</mu2>
            </ode>
          </friction>
        </surface>
      </collision>

      <sensor name="imu_sensor" type="imu">
        <pose>0 0 0 0 0 0</pose>
        <always_on>1</always_on>
        <update_rate>1000.0</update_rate>
      </sensor>
      <light name="light1" type="spot">
        <pose relative_to="base_link">0.18011 -0.056687 0.045 0 -1.5708 0</pose>
        <diffuse>1 1 1 1</diffuse>
        <specular>0.1 0.1 0.1 1</specular>
        <spot>
          <inner_angle>0.3</inner_angle>
          <outer_angle>0.7</outer_angle>
          <falloff>0.9</falloff>
        </spot>
        <attenuation>
          <range>8</range>
          <constant>0.5</constant>
          <linear>0.01</linear>
          <quadratic>0.001</quadratic>
        </attenuation>
        <intensity>0.0</intensity>
        <cast_shadows>false</cast_shadows>
      </light>
      <light name="light2" type="spot">
        <pose relative_to="base_link">0.18011 0.056687 0.045 0 -1.5708 0</pose>
        <diffuse>1 1 1 1</diffuse>
        <specular>0.1 0.1 0.1 1</specular>
        <spot>
          <inner_angle>0.3</inner_angle>
          <outer_angle>0.7</outer_angle>
          <falloff>0.9</falloff>
        </spot>
        <attenuation>
          <range>8</range>
          <constant>0.5</constant>
          <linear>0.01</linear>
          <quadratic>0.001</quadratic>
        </attenuation>
        <intensity>0.0</intensity>
        <cast_shadows>false</cast_shadows>
      </light>
    </link>

    <link name="camera_link">
      <pose relative_to="camera_mount_link">0 0 0 0 0 0</pose>
      <inertial>
        <mass>0.0001</mass>
        <inertia>
          <ixx>0.0001</ixx>
          <ixy>0</ixy>
          <ixz>0</ixz>
          <iyy>0.0001</iyy>
          <iyz>0</iyz>
          <izz>0.0001</izz>
        </inertia>
      </inertial>
      <sensor name="camera_sensor" type="camera">
        <update_rate>15</update_rate>
        <visualize>1</visualize>
        <always_on>1</always_on>
        <topic>/model/mud/camera</topic>
        <camera>
          <horizontal_fov>1.05</horizontal_fov>
          <image>
            <width>1280</width>
            <height>720</height>
            <format>R8G8B8</format>
          </image>
          <clip>
            <near>0.1</near>
            <far>10.0</far>
          </clip>
        </camera>
      </sensor>
    </link>
    <link name="camera_mount_link">
      <pose relative_to="base_link">0.325 0 0 0 0 0</pose>
      <inertial>
        <mass>0.0001</mass>
        <inertia>
          <ixx>0.0001</ixx>
          <ixy>0</ixy>
          <ixz>0</ixz>
          <iyy>0.0001</iyy>
          <iyz>0</iyz>
          <izz>0.0001</izz>
        </inertia>
      </inertial>
    </link>
    <joint name="camera_tilt_joint" type="revolute">
      <parent>camera_mount_link</parent>
      <child>camera_link</child>
      <axis>
        <xyz>0 1 0</xyz>
        <limit>
          <lower>-0.785398</lower>
          <upper>0.785398</upper>
        </limit>
      </axis>
    </joint>
    <joint name="camera_mount_joint" type="fixed">
      <parent>base_link</parent>
      <child>camera_mount_link</child>
    </joint>

    <link name="tether_mount">
      <pose>0.315 0 0.03 0 0 0</pose>
      <inertial>
        <mass>1e-6</mass>
        <inertia>
          <ixx>1e-9</ixx>
          <ixy>0</ixy>
          <ixz>0</ixz>
          <iyy>1e-9</iyy>
          <iyz>0</iyz>
          <izz>1e-9</izz>
        </inertia>
      </inertial>
    </link>

    <link name="thruster1">
      <pose>0.22067 0.097356 0 -1.571 1.571 -2.356</pose>
      <visual name="thruster_prop_visual">
        <pose>0 0 0 -1.571 0 0</pose>
        <geometry>
          <mesh>
            <uri>model://mud/meshes/ccw_prop.dae</uri>
          </mesh>
        </geometry>
      </visual>
      <inertial>
        <mass>0.002</mass>
        <inertia>
          <ixx>0.001</ixx>
          <ixy>0</ixy>
          <ixz>0</ixz>
          <iyy>0.001</iyy>
          <iyz>0</iyz>
          <izz>0.001</izz>
        </inertia>
      </inertial>
    </link>

    <link name="thruster2">
      <pose>0.22067 -0.097356 0 -1.571 1.571 -0.785</pose>
      <visual name="thruster_prop_visual">
        <pose>0 0 0 -1.571 0 0</pose>
        <geometry>
          <mesh>
            <uri>model://mud/meshes/ccw_prop.dae</uri>
          </mesh>
        </geometry>
      </visual>
      <inertial>
        <mass>0.002</mass>
        <inertia>
          <ixx>0.001</ixx>
          <ixy>0</ixy>
          <ixz>0</ixz>
          <iyy>0.001</iyy>
          <iyz>0</iyz>
          <izz>0.001</izz>
        </inertia>
      </inertial>
    </link>

    <link name="thruster3">
      <pose>-0.22067 0.097356 0 -1.571 1.571 2.356</pose>
      <visual name="thruster_prop_visual">
        <pose>0 0 0 1.571 0 0</pose>
        <geometry>
          <mesh>
            <uri>model://mud/meshes/cw_prop.dae</uri>
          </mesh>
        </geometry>
      </visual>
      <inertial>
        <mass>0.002</mass>
        <inertia>
          <ixx>0.001</ixx>
          <ixy>0</ixy>
          <ixz>0</ixz>
          <iyy>0.001</iyy>
          <iyz>0</iyz>
          <izz>0.001</izz>
        </inertia>
      </inertial>
    </link>

    <link name="thruster4">
      <pose>-0.22067 -0.097356 0 -1.571 1.571 0.785</pose>
      <visual name="thruster_prop_visual">
        <pose>0 0 0 1.571 0 0</pose>
        <geometry>
          <mesh>
            <uri>model://mud/meshes/cw_prop.dae</uri>
          </mesh>
        </geometry>
      </visual>
      <inertial>
        <mass>0.002</mass>
        <inertia>
          <ixx>0.001</ixx>
          <ixy>0</ixy>
          <ixz>0</ixz>
          <iyy>0.001</iyy>
          <iyz>0</iyz>
          <izz>0.001</izz>
        </inertia>
      </inertial>
    </link>

    <link name="thruster5">
      <pose>0.147024 0.100606 0 0 0 0</pose>
      <visual name="thruster_prop_visual">
        <pose>0 0 0 -1.571 0 1.571</pose>
        <geometry>
          <mesh>
            <uri>model://mud/meshes/ccw_prop.dae</uri>
          </mesh>
        </geometry>
      </visual>
      <inertial>
        <mass>0.002</mass>
        <inertia>
          <ixx>0.001</ixx>
          <ixy>0</ixy>
          <ixz>0</ixz>
          <iyy>0.001</iyy>
          <iyz>0</iyz>
          <izz>0.001</izz>
        </inertia>
      </inertial>
    </link>

    <link name="thruster6">
      <pose>0.147024 -0.100606 0 0 0 0</pose>
      <visual name="thruster_prop_visual">
        <pose>0 0 0 1.571 0 1.571</pose>
        <geometry>
          <mesh>
            <uri>model://mud/meshes/cw_prop.dae</uri>
          </mesh>
        </geometry>
      </visual>
      <inertial>
        <mass>0.002</mass>
        <inertia>
          <ixx>0.001</ixx>
          <ixy>0</ixy>
          <ixz>0</ixz>
          <iyy>0.001</iyy>
          <iyz>0</iyz>
          <izz>0.001</izz>
        </inertia>
      </inertial>
    </link>

    <link name="thruster7">
      <pose>-0.147024 0.100606 0 0 0 0</pose>
      <visual name="thruster_prop_visual">
        <pose>0 0 0 1.571 0 1.571</pose>
        <geometry>
          <mesh>
            <uri>model://mud/meshes/ccw_prop.dae</uri>
          </mesh>
        </geometry>
      </visual>
      <inertial>
        <mass>0.002</mass>
        <inertia>
          <ixx>0.001</ixx>
          <ixy>0</ixy>
          <ixz>0</ixz>
          <iyy>0.001</iyy>
          <iyz>0</iyz>
          <izz>0.001</izz>
        </inertia>
      </inertial>
    </link>

    <link name="thruster8">
      <pose>-0.147024 -0.100606 0 0 0 0</pose>
      <visual name="thruster_prop_visual">
        <pose>0 0 0 1.571 0 1.571</pose>
        <geometry>
          <mesh>
            <uri>model://mud/meshes/ccw_prop.dae</uri>
          </mesh>
        </geometry>
      </visual>
      <inertial>
        <mass>0.002</mass>
        <inertia>
          <ixx>0.001</ixx>
          <ixy>0</ixy>
          <ixz>0</ixz>
          <iyy>0.001</iyy>
          <iyz>0</iyz>
          <izz>0.001</izz>
        </inertia>
      </inertial>
    </link>

    <joint name="thruster1_joint" type="revolute">
      <parent>base_link</parent>
      <child>thruster1</child>
      <axis>
        <xyz>0 0 -1</xyz>
      </axis>
    </joint>

    <joint name="thruster2_joint" type="revolute">
      <parent>base_link</parent>
      <child>thruster2</child>
      <axis>
        <xyz>0 0 -1</xyz>
      </axis>
    </joint>

    <joint name="thruster3_joint" type="revolute">
      <parent>base_link</parent>
      <child>thruster3</child>
      <axis>
        <xyz>0 0 -1</xyz>
      </axis>
    </joint>

    <joint name="thruster4_joint" type="revolute">
      <parent>base_link</parent>
      <child>thruster4</child>
      <axis>
        <xyz>0 0 -1</xyz>
      </axis>
    </joint>

    <joint name="thruster5_joint" type="revolute">
      <parent>base_link</parent>
      <child>thruster5</child>
      <axis>
        <xyz>0 0 -1</xyz>
      </axis>
    </joint>

    <joint name="thruster6_joint" type="revolute">
      <parent>base_link</parent>
      <child>thruster6</child>
      <axis>
        <xyz>0 0 -1</xyz>
      </axis>
    </joint>

    <joint name="thruster7_joint" type="revolute">
      <parent>base_link</parent>
      <child>thruster7</child>
      <axis>
        <xyz>0 0 -1</xyz>
      </axis>
    </joint>

    <joint name="thruster8_joint" type="revolute">
      <parent>base_link</parent>
      <child>thruster8</child>
      <axis>
        <xyz>0 0 -1</xyz>
      </axis>
    </joint>

    <!-- Hydrodynamics plugin -->
    <plugin
        filename="gz-sim-hydrodynamics-system"
        name="gz::sim::systems::Hydrodynamics">
      <link_name>base_link</link_name>
      <water_density>1025.0</water_density>

      <xDotU>0</xDotU>
      <yDotV>0</yDotV>
      <zDotW>0</zDotW>
      <kDotP>0</kDotP>
      <mDotQ>0</mDotQ>
      <nDotR>0</nDotR>

      <xU>0</xU>
      <yV>0</yV>
      <zW>0</zW>
      <kP>0</kP>
      <mQ>0</mQ>
      <nR>0</nR>

      <xUabsU>-33.732</xUabsU>
      <yVabsV>-54.16</yVabsV>
      <zWabsW>-73.225</zWabsW>
      <kPabsP>-25</kPabsP>
      <mQabsQ>-25</mQabsQ>
      <nRabsR>-12</nRabsR>
    </plugin>

    <plugin
        filename="gz-sim-thruster-system"
        name="gz::sim::systems::Thruster">
      <namespace>mud</namespace>
      <joint_name>thruster1_joint</joint_name>
      <thrust_coefficient>0.01</thrust_coefficient>
      <fluid_density>1025.0</fluid_density>
      <propeller_diameter>0.07</propeller_diameter>
      <use_angvel_cmd>False</use_angvel_cmd>
    </plugin>

    <plugin
        filename="gz-sim-thruster-system"
        name="gz::sim::systems::Thruster">
      <namespace>mud</namespace>
      <joint_name>thruster2_joint</joint_name>
      <thrust_coefficient>0.01</thrust_coefficient>
      <fluid_density>1025.0</fluid_density>
      <propeller_diameter>0.07</propeller_diameter>
      <use_angvel_cmd>False</use_angvel_cmd>
    </plugin>

    <plugin
        filename="gz-sim-thruster-system"
        name="gz::sim::systems::Thruster">
      <namespace>mud</namespace>
      <joint_name>thruster3_joint</joint_name>
      <!-- Reverse spin to balance torque -->
      <thrust_coefficient>-0.01</thrust_coefficient>
      <fluid_density>1025.0</fluid_density>
      <propeller_diameter>0.07</propeller_diameter>
      <use_angvel_cmd>False</use_angvel_cmd>
    </plugin>

    <plugin
        filename="gz-sim-thruster-system"
        name="gz::sim::systems::Thruster">
      <namespace>mud</namespace>
      <joint_name>thruster4_joint</joint_name>
      <!-- Reverse spin to balance torque -->
      <thrust_coefficient>-0.01</thrust_coefficient>
      <fluid_density>1025.0</fluid_density>
      <propeller_diameter>0.07</propeller_diameter>
      <use_angvel_cmd>False</use_angvel_cmd>
    </plugin>

    <plugin
        filename="gz-sim-thruster-system"
        name="gz::sim::systems::Thruster">
      <namespace>mud</namespace>
      <joint_name>thruster5_joint</joint_name>
      <thrust_coefficient>0.01</thrust_coefficient>
      <fluid_density>1025.0</fluid_density>
      <propeller_diameter>0.07</propeller_diameter>
      <use_angvel_cmd>False</use_angvel_cmd>
    </plugin>

    <plugin
        filename="gz-sim-thruster-system"
        name="gz::sim::systems::Thruster">
      <namespace>mud</namespace>
      <joint_name>thruster6_joint</joint_name>
      <!-- Reverse spin to balance torque -->
      <thrust_coefficient>-0.01</thrust_coefficient>
      <fluid_density>1025.0</fluid_density>
      <propeller_diameter>0.07</propeller_diameter>
      <use_angvel_cmd>False</use_angvel_cmd>
    </plugin>

    <plugin
        filename="gz-sim-thruster-system"
        name="gz::sim::systems::Thruster">
      <namespace>mud</namespace>
      <joint_name>thruster7_joint</joint_name>
      <!-- Reverse spin to balance torque -->
      <thrust_coefficient>-0.01</thrust_coefficient>
      <fluid_density>1025.0</fluid_density>
      <propeller_diameter>0.07</propeller_diameter>
      <use_angvel_cmd>False</use_angvel_cmd>
    </plugin>

    <plugin
        filename="gz-sim-thruster-system"
        name="gz::sim::systems::Thruster">
      <namespace>mud</namespace>
      <joint_name>thruster8_joint</joint_name>
      <!-- Reverse spin to balance torque -->
      <thrust_coefficient>-0.01</thrust_coefficient>
      <fluid_density>1025.0</fluid_density>
      <propeller_diameter>0.07</propeller_diameter>
      <use_angvel_cmd>False</use_angvel_cmd>
    </plugin>
    
    <plugin
      filename="gz-sim-odometry-publisher-system"
      name="gz::sim::systems::OdometryPublisher">
      <odom_frame>map</odom_frame>
      <robot_base_frame>base_link</robot_base_frame>
      <dimensions>3</dimensions>
      <odom_publish_frequency>100</odom_publish_frequency>
    </plugin>

    <plugin
      filename="gz-sim-joint-position-controller-system"
      name="gz::sim::systems::JointPositionController">
      <joint_name>camera_tilt_joint</joint_name>
      <topic>/model/mud/joint/camera_tilt_joint/cmd_pos</topic>
      <p_gain>2.0</p_gain>
    </plugin>

    <plugin
      filename="gz-sim-joint-state-publisher-system"
      name="gz::sim::systems::JointStatePublisher">
    </plugin>

    <plugin
      filename="ArduPilotPlugin"
      name="ArduPilotPlugin">
      <imuName>imu_sensor</imuName>

      <fdm_addr>127.0.0.1</fdm_addr>
      <fdm_port_in>9002</fdm_port_in>
      <fdm_port_out>9003</fdm_port_out>

      <lock_step>true</lock_step>
      <no_time_sync>true</no_time_sync>

      <control channel="0">
        <type>COMMAND</type>
        <jointName>thruster1_joint</jointName>
        <cmd_topic>/model/mud/joint/thruster1_joint/cmd_thrust</cmd_topic>
        <multiplier>1.0</multiplier>
        <offset>0.0</offset>
        <servo_min>1100</servo_min>
        <servo_max>1900</servo_max>
      </control>
      <control channel="1">
        <type>COMMAND</type>
        <jointName>thruster2_joint</jointName>
        <cmd_topic>/model/mud/joint/thruster2_joint/cmd_thrust</cmd_topic>
        <multiplier>1.0</multiplier>
        <offset>0.0</offset>
        <servo_min>1100</servo_min>
        <servo_max>1900</servo_max>
      </control>
      <control channel="2">
        <type>COMMAND</type>
        <jointName>thruster3_joint</jointName>
        <cmd_topic>/model/mud/joint/thruster3_joint/cmd_thrust</cmd_topic>
        <multiplier>1.0</multiplier>
        <offset>0.0</offset>
        <servo_min>1100</servo_min>
        <servo_max>1900</servo_max>
      </control>
      <control channel="3">
        <type>COMMAND</type>
        <jointName>thruster4_joint</jointName>
        <cmd_topic>/model/mud/joint/thruster4_joint/cmd_thrust</cmd_topic>
        <multiplier>1.0</multiplier>
        <offset>0.0</offset>
        <servo_min>1100</servo_min>
        <servo_max>1900</servo_max>
      </control>
      <control channel="4">
        <type>COMMAND</type>
        <jointName>thruster5_joint</jointName>
        <cmd_topic>/model/mud/joint/thruster5_joint/cmd_thrust</cmd_topic>
        <multiplier>1.0</multiplier>
        <offset>0.0</offset>
        <servo_min>1100</servo_min>
        <servo_max>1900</servo_max>
      </control>
      <control channel="5">
        <type>COMMAND</type>
        <jointName>thruster6_joint</jointName>
        <cmd_topic>/model/mud/joint/thruster6_joint/cmd_thrust</cmd_topic>
        <multiplier>1.0</multiplier>
        <offset>0.0</offset>
        <servo_min>1100</servo_min>
        <servo_max>1900</servo_max>
      </control>
      <control channel="6">
        <type>COMMAND</type>
        <jointName>thruster7_joint</jointName>
        <cmd_topic>/model/mud/joint/thruster7_joint/cmd_thrust</cmd_topic>
        <multiplier>1.0</multiplier>
        <offset>0.0</offset>
        <servo_min>1100</servo_min>
        <servo_max>1900</servo_max>
      </control>
      <control channel="7">
        <type>COMMAND</type>
        <jointName>thruster8_joint</jointName>
        <cmd_topic>/model/mud/joint/thruster8_joint/cmd_thrust</cmd_topic>
        <multiplier>1.0</multiplier>
        <offset>0.0</offset>
        <servo_min>1100</servo_min>
        <servo_max>1900</servo_max>
      </control>
    </plugin>

  </model>
</sdf>